Workbook

Sheet Dashboard
A2: Executive Dashboard
A4: Monthly Billing Tab | D4: Receipt Template | G4: Available Bed Spaces | J4: Arrears Report
G8: =Calc_Data!B8 -> 5500 | J8: Total Grace Period

Sheet Master Roster
A1: Master Roster | I1: All Available
D2: Search Tenant: | E2: Chanda Lutashima
A3: Unique ID | B3: Room Number | C3: House/ Block | D3: Bed Space | E3: Tenant Name | F3: Phone Number | G3: Entry Date | H3: Monthly Rent | I3: ID & Name | J3: Room Gender
A4: BBH-1-A | B4: 1 | C4: BBH | D4: A | E4: Adrian mulale | F4: 260977146630 | G4: 46203 | H4: 950 | I4: =A4 & " - " & E4 -> BBH-1-A - Adrian mulale | J4: Male
A5: BBH-2-A | B5: 2 | C5: BBH | D5: A | E5: Wisdom Bwani | F5: 260776960320 | G5: 46178 | H5: 900 | I5: =A5 & " - " & E5 -> BBH-2-A - Wisdom Bwani | J5: Male
A6: BBH-2-B | B6: 2 | C6: BBH | D6: B | E6: Jackson Mwanza | F6: 260976625656 | G6: 46181 | H6: 900 | I6: =A6 & " - " & E6 -> BBH-2-B - Jackson Mwanza | J6: Male
A7: BBH-3-A | B7: 3 | C7: BBH | D7: A | E7: Prosper Kalayi | F7: 260970522913 | G7: 46186 | H7: 900 | I7: =A7 & " - " & E7 -> BBH-3-A - Prosper Kalayi | J7: Male
A8: BBH-3-B | B8: 3 | C8: BBH | D8: B | E8: Shadrach Munganini | F8: 260979567550 | G8: 46228 | H8: 900 | I8: =A8 & " - " & E8 -> BBH-3-B - Shadrach Munganini | J8: Male
A9: BBH-3-C | B9: 3 | C9: BBH | D9: C | E9: Collins Mubanga | F9: 260777237029 | G9: 46176 | H9: 900 | I9: =A9 & " - " & E9 -> BBH-3-C - Collins Mubanga | J9: Male
A10: BBH-4-A | B10: 4 | C10: BBH | D10: A | E10: Himalikiti Saviour | F10: 260975547126 | G10: 46195 | H10: 950 | I10: =A10 & " - " & E10 -> BBH-4-A - Himalikiti Saviour | J10: Male
A11: BBH-5-A | B11: 5 | C11: BBH | D11: A | E11: Wampa | F11: 260971071877 | G11: 46225 | H11: 0 | I11: =A11 & " - " & E11 -> BBH-5-A - Wampa | J11: Female
A12: BBH-6-A | B12: 6 | C12: BBH | D12: A | E12: McDonald | F12: 260773456119 | G12: 46174 | H12: 900 | I12: =A12 & " - " & E12 -> BBH-6-A - McDonald | J12: Male
A13: BBH-6-B | B13: 6 | C13: BBH | D13: B | E13: Nanga Obrien | F13: 260770838758 | G13: 46048 | H13: 900 | I13: =A13 & " - " & E13 -> BBH-6-B - Nanga Obrien | J13: Male
A14: BBH-6-C | B14: 6 | C14: BBH | D14: C | E14: Zick Phiri | F14: 260973072762 | G14: 46184 | H14: 900 | I14: =A14 & " - " & E14 -> BBH-6-C - Zick Phiri | J14: Male
A15: BBH-7-A | B15: 7 | C15: BBH | D15: A | E15: Funny Muyamina | F15: 260771096585 | G15: 46178 | H15: 900 | I15: =A15 & " - " & E15 -> BBH-7-A - Funny Muyamina | J15: Female
A16: BBH-7-B | B16: 7 | C16: BBH | D16: B | E16: Treasure Simeenda | F16: 260772393278 | G16: 46178 | H16: 900 | I16: =A16 & " - " & E16 -> BBH-7-B - Treasure Simeenda | J16: Female
A17: BBH-7-C | B17: 7 | C17: BBH | D17: C | E17: Vacant | H17: 900 | I17: =A17 & " - " & E17 -> BBH-7-C - Vacant | J17: Female
A18: BBH-8-A | B18: 8 | C18: BBH | D18: A | E18: Kangwa Kunda | F18: 260972024337 | G18: 46198 | H18: 900 | I18: =A18 & " - " & E18 -> BBH-8-A - Kangwa Kunda | J18: Male
A19: BBH-8-B | B19: 8 | C19: BBH | D19: B | E19: Vacant | H19: 900 | I19: =A19 & " - " & E19 -> BBH-8-B - Vacant | J19: Male
A20: BBH-9-A | B20: 9 | C20: BBH | D20: A | E20: Felistus Mweemba | F20: 260764785030 | G20: 46182 | H20: 900 | I20: =A20 & " - " & E20 -> BBH-9-A - Felistus Mweemba | J20: Female
A21: BBH-9-B | B21: 9 | C21: BBH | D21: B | E21: Wendy Mpakise | F21: 260971977845 | G21: 46200 | H21: 900 | I21: =A21 & " - " & E21 -> BBH-9-B - Wendy Mpakise | J21: Female
A22: BBH-9-C | B22: 9 | C22: BBH | D22: C | E22: Vacant | H22: 900 | I22: =A22 & " - " & E22 -> BBH-9-C - Vacant | J22: Female
A23: UPV-10-A | B23: 10 | C23: UPV | D23: A | E23: Emely Mwale | F23: 260777238633 | G23: 46178 | H23: 900 | I23: =A23 & " - " & E23 -> UPV-10-A - Emely Mwale | J23: Female
A24: UPV-10-B | B24: 10 | C24: UPV | D24: B | E24: Melody Mumba | F24: 260973551911 | G24: 46186 | H24: 900 | I24: =A24 & " - " & E24 -> UPV-10-B - Melody Mumba | J24: Female
A25: UPV-10-C | B25: 10 | C25: UPV | D25: C | E25: Sara Matakala | F25: 260970522825 | G25: 46198 | H25: 900 | I25: =A25 & " - " & E25 -> UPV-10-C - Sara Matakala | J25: Female
A26: UPV-10-D | B26: 10 | C26: UPV | D26: D | E26: Vacant | H26: 900 | I26: =A26 & " - " & E26 -> UPV-10-D - Vacant | J26: Female
A27: UPV-11-A | B27: 11 | C27: UPV | D27: A | E27: Gift Nankamba | F27: 260970956759 | G27: 46178 | H27: 1000 | I27: =A27 & " - " & E27 -> UPV-11-A - Gift Nankamba | J27: Female
A28: UPV-12-A | B28: 12 | C28: UPV | D28: A | E28: chilulu chiliulu | F28: 260975185330 | G28: 46182 | H28: 1600 | I28: =A28 & " - " & E28 -> UPV-12-A - chilulu chiliulu | J28: Male
A29: UPV-13-A | B29: 13 | C29: UPV | D29: A | E29: Chibesa Chisembe | F29: 260970270037 | G29: 46175 | H29: 1800 | I29: =A29 & " - " & E29 -> UPV-13-A - Chibesa Chisembe | J29: Male
A30: UPV-14-A | B30: 14 | C30: UPV | D30: A | E30: Reuben Ngusulu | F30: 260763503053 | G30: 46184 | H30: 950 | I30: =A30 & " - " & E30 -> UPV-14-A - Reuben Ngusulu | J30: Male
A31: UPV-15-A | B31: 15 | C31: UPV | D31: A | E31: Harriet nanyangwe | F31: 260974130584 | G31: 46176 | H31: 1100 | I31: =A31 & " - " & E31 -> UPV-15-A - Harriet nanyangwe | J31: Female
A32: CRV-16-A | B32: 16 | C32: CRV | D32: A | E32: Vacant | F32: 20772046008 | G32: 46223 | H32: 0 | I32: =A32 & " - " & E32 -> CRV-16-A - Vacant | J32: Male
A33: CRV-16-B | B33: 16 | C33: CRV | D33: B | E33: Ackim Siamafuko | F33: 20772046008 | G33: 46223 | H33: 1200 | I33: =A33 & " - " & E33 -> CRV-16-B - Ackim Siamafuko | J33: Male
A34: CRV-17-A | B34: 17 | C34: CRV | D34: A | E34: Kwitu Khalu | F34: 260960785114 | G34: 46175 | H34: 900 | I34: =A34 & " - " & E34 -> CRV-17-A - Kwitu Khalu | J34: Male
A35: CRV-18-A | B35: 18 | C35: CRV | D35: A | E35: Christopher Tambule | F35: 260972108866 | G35: 46190 | H35: 1200 | I35: =A35 & " - " & E35 -> CRV-18-A - Christopher Tambule | J35: Male
A36: ANX-19-A | B36: 19 | C36: ANX | D36: A | E36: Samantha Musako (Kakompe) | F36: 260977227794 | G36: 46199 | H36: 1200 | I36: =A36 & " - " & E36 -> ANX-19-A - Samantha Musako (Kakompe) | J36: Female
A37: ANX-19-B | B37: 19 | C37: ANX | D37: B | E37: Chanda Lutashima | F37: 260977951894 | G37: 46180 | H37: 1200 | I37: =A37 & " - " & E37 -> ANX-19-B - Chanda Lutashima | J37: Female
A38: ANX-19-C | B38: 19 | C38: ANX | D38: C | E38: Josephine Nyirenda | F38: 260779841908 | G38: 46148 | H38: 1200 | I38: =A38 & " - " & E38 -> ANX-19-C - Josephine Nyirenda | J38: Female
A39: ANX-19-D | B39: 19 | C39: ANX | D39: D | E39: Lubono Ruthendo | F39: 260953618278 | G39: 46207 | H39: 1200 | I39: =A39 & " - " & E39 -> ANX-19-D - Lubono Ruthendo | J39: Female
A40: ANX-20-A | B40: 20 | C40: ANX | D40: A | E40: Steven Musonda | F40: 260975303236 | G40: 46178 | H40: 1400 | I40: =A40 & " - " & E40 -> ANX-20-A - Steven Musonda | J40: Male
...

Sheet Arrears Report
A1: Arrears Report
F2: =SUM(F4:F1002) -> 21950
A3: Tenant Name | B3: Phone Number | C3: Unique ID | D3: Due Date | E3: Days Overdue | F3: Total Balance | G3: Send via WhatsApp | H3: Send via SMS?
A4: =IFERROR(__xludf.DUMMYFUNCTION("FILTER({'Monthly Billing Tab'!D4:D1002, 'Monthly Billing Tab'!E4:E1002, 'Monthly Billing Tab'!B4:B1002, 'Monthly Billing Tab'!J4:J1002, TODAY() - DATE(YEAR(TODAY()), MONTH('Monthly Billing Tab'!J4:J1002&"" 1""), DAY('Monthly Billing Tab'!G4:G1002)), 'Mont"&"hly Billing Tab'!L4:L1002}, 'Monthly Billing Tab'!D4:D1002<>""Vacant"", 'Monthly Billing Tab'!D4:D1002<>""Reserved"", 'Monthly Billing Tab'!D4:D1002<>"""", 'Monthly Billing Tab'!M4:M1002=""❌ OVERDUE / UNPAID"")"),"Jackson Mwanza") -> Jackson Mwanza | B4: =IFERROR(__xludf.DUMMYFUNCTION("""COMPUTED_VALUE"""),"260976625656") -> 260976625656 | C4: =IFERROR(__xludf.DUMMYFUNCTION("""COMPUTED_VALUE"""),"BBH-2-B") -> BBH-2-B | D4: =IFERROR(__xludf.DUMMYFUNCTION("""COMPUTED_VALUE"""),"Jul") -> Jul | E4: =IFERROR(__xludf.DUMMYFUNCTION("""COMPUTED_VALUE"""),61.0) -> 61 | F4: =IFERROR(__xludf.DUMMYFUNCTION("""COMPUTED_VALUE"""),1200.0) -> 1200 | G4: =IF(A4="", "", HYPERLINK("https://wa.me/" & B4 & "?text=" & ENCODEURL("Hello " & IF(IFERROR(VLOOKUP(C4, 'Master Roster'!A:J, 10, FALSE), "")="Male", "Mr. ", "Ms. ") & A4 & ", this is a reminder that your rent balance of K" & F4 & " is due. Please make a payment,"), "Message on WhatsApp")) -> Message on WhatsApp | H4: =IF(ISBLANK(A4), "", HYPERLINK("sms:"&B4&"?body=Hello "&A4&", this is a reminder that your rent balance of "&F4&" is overdue.", "Send SMS")) -> Send SMS
A5: =IFERROR(__xludf.DUMMYFUNCTION("""COMPUTED_VALUE"""),"Himalikiti Saviour") -> Himalikiti Saviour | B5: =IFERROR(__xludf.DUMMYFUNCTION("""COMPUTED_VALUE"""),2.60975547126E11) -> 260975547126 | C5: =IFERROR(__xludf.DUMMYFUNCTION("""COMPUTED_VALUE"""),"BBH-4-A") -> BBH-4-A | D5: =IFERROR(__xludf.DUMMYFUNCTION("""COMPUTED_VALUE"""),"Jul") -> Jul | E5: =IFERROR(__xludf.DUMMYFUNCTION("""COMPUTED_VALUE"""),47.0) -> 47 | F5: =IFERROR(__xludf.DUMMYFUNCTION("""COMPUTED_VALUE"""),1900.0) -> 1900 | G5: =IF(A5="", "", HYPERLINK("https://wa.me/" & B5 & "?text=" & ENCODEURL("Hello " & IF(IFERROR(VLOOKUP(C5, 'Master Roster'!A:J, 10, FALSE), "")="Male", "Mr. ", "Ms. ") & A5 & ", this is a reminder that your rent balance of K" & F5 & " is due. Please make a payment,"), "Message on WhatsApp")) -> Message on WhatsApp | H5: =IF(ISBLANK(A5), "", HYPERLINK("sms:"&B5&"?body=Hello "&A5&", this is a reminder that your rent balance of "&F5&" is overdue.", "Send SMS")) -> Send SMS
A6: =IFERROR(__xludf.DUMMYFUNCTION("""COMPUTED_VALUE"""),"McDonald") -> McDonald | B6: =IFERROR(__xludf.DUMMYFUNCTION("""COMPUTED_VALUE"""),2.60773456119E11) -> 260773456119 | C6: =IFERROR(__xludf.DUMMYFUNCTION("""COMPUTED_VALUE"""),"BBH-6-A") -> BBH-6-A | D6: =IFERROR(__xludf.DUMMYFUNCTION("""COMPUTED_VALUE"""),"May") -> May | E6: =IFERROR(__xludf.DUMMYFUNCTION("""COMPUTED_VALUE"""),129.0) -> 129 | F6: =IFERROR(__xludf.DUMMYFUNCTION("""COMPUTED_VALUE"""),2600.0) -> 2600 | G6: =IF(A6="", "", HYPERLINK("https://wa.me/" & B6 & "?text=" & ENCODEURL("Hello " & IF(IFERROR(VLOOKUP(C6, 'Master Roster'!A:J, 10, FALSE), "")="Male", "Mr. ", "Ms. ") & A6 & ", this is a reminder that your rent balance of K" & F6 & " is due. Please make a payment,"), "Message on WhatsApp")) -> Message on WhatsApp | H6: =IF(ISBLANK(A6), "", HYPERLINK("sms:"&B6&"?body=Hello "&A6&", this is a reminder that your rent balance of "&F6&" is overdue.", "Send SMS")) -> Send SMS
A7: =IFERROR(__xludf.DUMMYFUNCTION("""COMPUTED_VALUE"""),"Nanga Obrien") -> Nanga Obrien | B7: =IFERROR(__xludf.DUMMYFUNCTION("""COMPUTED_VALUE"""),2.60770838758E11) -> 260770838758 | C7: =IFERROR(__xludf.DUMMYFUNCTION("""COMPUTED_VALUE"""),"BBH-6-B") -> BBH-6-B | D7: =IFERROR(__xludf.DUMMYFUNCTION("""COMPUTED_VALUE"""),"May") -> May | E7: =IFERROR(__xludf.DUMMYFUNCTION("""COMPUTED_VALUE"""),104.0) -> 104 | F7: =IFERROR(__xludf.DUMMYFUNCTION("""COMPUTED_VALUE"""),3600.0) -> 3600 | G7: =IF(A7="", "", HYPERLINK("https://wa.me/" & B7 & "?text=" & ENCODEURL("Hello " & IF(IFERROR(VLOOKUP(C7, 'Master Roster'!A:J, 10, FALSE), "")="Male", "Mr. ", "Ms. ") & A7 & ", this is a reminder that your rent balance of K" & F7 & " is due. Please make a payment,"), "Message on WhatsApp")) -> Message on WhatsApp | H7: =IF(ISBLANK(A7), "", HYPERLINK("sms:"&B7&"?body=Hello "&A7&", this is a reminder that your rent balance of "&F7&" is overdue.", "Send SMS")) -> Send SMS
A8: =IFERROR(__xludf.DUMMYFUNCTION("""COMPUTED_VALUE"""),"Wendy Mpakise") -> Wendy Mpakise | B8: =IFERROR(__xludf.DUMMYFUNCTION("""COMPUTED_VALUE"""),2.60971977845E11) -> 260971977845 | C8: =IFERROR(__xludf.DUMMYFUNCTION("""COMPUTED_VALUE"""),"BBH-9-B") -> BBH-9-B | D8: =IFERROR(__xludf.DUMMYFUNCTION("""COMPUTED_VALUE"""),"Jul") -> Jul | E8: =IFERROR(__xludf.DUMMYFUNCTION("""COMPUTED_VALUE"""),42.0) -> 42 | F8: =IFERROR(__xludf.DUMMYFUNCTION("""COMPUTED_VALUE"""),1800.0) -> 1800 | G8: =IF(A8="", "", HYPERLINK("https://wa.me/" & B8 & "?text=" & ENCODEURL("Hello " & IF(IFERROR(VLOOKUP(C8, 'Master Roster'!A:J, 10, FALSE), "")="Male", "Mr. ", "Ms. ") & A8 & ", this is a reminder that your rent balance of K" & F8 & " is due. Please make a payment,"), "Message on WhatsApp")) -> Message on WhatsApp | H8: =IF(ISBLANK(A8), "", HYPERLINK("sms:"&B8&"?body=Hello "&A8&", this is a reminder that your rent balance of "&F8&" is overdue.", "Send SMS")) -> Send SMS
A9: =IFERROR(__xludf.DUMMYFUNCTION("""COMPUTED_VALUE"""),"Lukundo Siame") -> Lukundo Siame | B9: =IFERROR(__xludf.DUMMYFUNCTION("""COMPUTED_VALUE"""),2.60760833629E11) -> 260760833629 | C9: =IFERROR(__xludf.DUMMYFUNCTION("""COMPUTED_VALUE"""),"NWG-21-A") -> NWG-21-A | D9: =IFERROR(__xludf.DUMMYFUNCTION("""COMPUTED_VALUE"""),"Jul") -> Jul | E9: =IFERROR(__xludf.DUMMYFUNCTION("""COMPUTED_VALUE"""),51.0) -> 51 | F9: =IFERROR(__xludf.DUMMYFUNCTION("""COMPUTED_VALUE"""),1250.0) -> 1250 | G9: =IF(A9="", "", HYPERLINK("https://wa.me/" & B9 & "?text=" & ENCODEURL("Hello " & IF(IFERROR(VLOOKUP(C9, 'Master Roster'!A:J, 10, FALSE), "")="Male", "Mr. ", "Ms. ") & A9 & ", this is a reminder that your rent balance of K" & F9 & " is due. Please make a payment,"), "Message on WhatsApp")) -> Message on WhatsApp | H9: =IF(ISBLANK(A9), "", HYPERLINK("sms:"&B9&"?body=Hello "&A9&", this is a reminder that your rent balance of "&F9&" is overdue.", "Send SMS")) -> Send SMS
A10: =IFERROR(__xludf.DUMMYFUNCTION("""COMPUTED_VALUE"""),"Gabirel Kabwe") -> Gabirel Kabwe | B10: =IFERROR(__xludf.DUMMYFUNCTION("""COMPUTED_VALUE"""),2.60968723095E11) -> 260968723095 | C10: =IFERROR(__xludf.DUMMYFUNCTION("""COMPUTED_VALUE"""),"NWG-21-B") -> NWG-21-B | D10: =IFERROR(__xludf.DUMMYFUNCTION("""COMPUTED_VALUE"""),"Aug") -> Aug | E10: =IFERROR(__xludf.DUMMYFUNCTION("""COMPUTED_VALUE"""),37.0) -> 37 | F10: =IFERROR(__xludf.DUMMYFUNCTION("""COMPUTED_VALUE"""),1200.0) -> 1200 | G10: =IF(A10="", "", HYPERLINK("https://wa.me/" & B10 & "?text=" & ENCODEURL("Hello " & IF(IFERROR(VLOOKUP(C10, 'Master Roster'!A:J, 10, FALSE), "")="Male", "Mr. ", "Ms. ") & A10 & ", this is a reminder that your rent balance of K" & F10 & " is due. Please make a payment,"), "Message on WhatsApp")) -> Message on WhatsApp | H10: =IF(ISBLANK(A10), "", HYPERLINK("sms:"&B10&"?body=Hello "&A10&", this is a reminder that your rent balance of "&F10&" is overdue.", "Send SMS")) -> Send SMS
A11: =IFERROR(__xludf.DUMMYFUNCTION("""COMPUTED_VALUE"""),"Chama Kampamba") -> Chama Kampamba | B11: =IFERROR(__xludf.DUMMYFUNCTION("""COMPUTED_VALUE"""),2.60770055753E11) -> 260770055753 | C11: =IFERROR(__xludf.DUMMYFUNCTION("""COMPUTED_VALUE"""),"NWG-21-C") -> NWG-21-C | D11: =IFERROR(__xludf.DUMMYFUNCTION("""COMPUTED_VALUE"""),"Jul") -> Jul | E11: =IFERROR(__xludf.DUMMYFUNCTION("""COMPUTED_VALUE"""),63.0) -> 63 | F11: =IFERROR(__xludf.DUMMYFUNCTION("""COMPUTED_VALUE"""),2400.0) -> 2400 | G11: =IF(A11="", "", HYPERLINK("https://wa.me/" & B11 & "?text=" & ENCODEURL("Hello " & IF(IFERROR(VLOOKUP(C11, 'Master Roster'!A:J, 10, FALSE), "")="Male", "Mr. ", "Ms. ") & A11 & ", this is a reminder that your rent balance of K" & F11 & " is due. Please make a payment,"), "Message on WhatsApp")) -> Message on WhatsApp | H11: =IF(ISBLANK(A11), "", HYPERLINK("sms:"&B11&"?body=Hello "&A11&", this is a reminder that your rent balance of "&F11&" is overdue.", "Send SMS")) -> Send SMS
A12: =IFERROR(__xludf.DUMMYFUNCTION("""COMPUTED_VALUE"""),"Chansa Chinyama") -> Chansa Chinyama | B12: =IFERROR(__xludf.DUMMYFUNCTION("""COMPUTED_VALUE"""),2.60974051468E11) -> 260974051468 | C12: =IFERROR(__xludf.DUMMYFUNCTION("""COMPUTED_VALUE"""),"NWG-24-C") -> NWG-24-C | D12: =IFERROR(__xludf.DUMMYFUNCTION("""COMPUTED_VALUE"""),"Jul") -> Jul | E12: =IFERROR(__xludf.DUMMYFUNCTION("""COMPUTED_VALUE"""),53.0) -> 53 | F12: =IFERROR(__xludf.DUMMYFUNCTION("""COMPUTED_VALUE"""),2400.0) -> 2400 | G12: =IF(A12="", "", HYPERLINK("https://wa.me/" & B12 & "?text=" & ENCODEURL("Hello " & IF(IFERROR(VLOOKUP(C12, 'Master Roster'!A:J, 10, FALSE), "")="Male", "Mr. ", "Ms. ") & A12 & ", this is a reminder that your rent balance of K" & F12 & " is due. Please make a payment,"), "Message on WhatsApp")) -> Message on WhatsApp | H12: =IF(ISBLANK(A12), "", HYPERLINK("sms:"&B12&"?body=Hello "&A12&", this is a reminder that your rent balance of "&F12&" is overdue.", "Send SMS")) -> Send SMS
A13: =IFERROR(__xludf.DUMMYFUNCTION("""COMPUTED_VALUE"""),"Kawina Florence") -> Kawina Florence | B13: =IFERROR(__xludf.DUMMYFUNCTION("""COMPUTED_VALUE"""),2.60976534878E11) -> 260976534878 | C13: =IFERROR(__xludf.DUMMYFUNCTION("""COMPUTED_VALUE"""),"NWG-24-D") -> NWG-24-D | D13: =IFERROR(__xludf.DUMMYFUNCTION("""COMPUTED_VALUE"""),"Jun") -> Jun | E13: =IFERROR(__xludf.DUMMYFUNCTION("""COMPUTED_VALUE"""),92.0) -> 92 | F13: =IFERROR(__xludf.DUMMYFUNCTION("""COMPUTED_VALUE"""),3600.0) -> 3600 | G13: =IF(A13="", "", HYPERLINK("https://wa.me/" & B13 & "?text=" & ENCODEURL("Hello " & IF(IFERROR(VLOOKUP(C13, 'Master Roster'!A:J, 10, FALSE), "")="Male", "Mr. ", "Ms. ") & A13 & ", this is a reminder that your rent balance of K" & F13 & " is due. Please make a payment,"), "Message on WhatsApp")) -> Message on WhatsApp | H13: =IF(ISBLANK(A13), "", HYPERLINK("sms:"&B13&"?body=Hello "&A13&", this is a reminder that your rent balance of "&F13&" is overdue.", "Send SMS")) -> Send SMS
G14: =IF(A14="", "", HYPERLINK("https://wa.me/" & B14 & "?text=" & ENCODEURL("Hello " & IF(IFERROR(VLOOKUP(C14, 'Master Roster'!A:J, 10, FALSE), "")="Male", "Mr. ", "Ms. ") & A14 & ", this is a reminder that your rent balance of K" & F14 & " is due. Please make a payment,"), "Message on WhatsApp")) | H14: =IF(ISBLANK(A14), "", HYPERLINK("sms:"&B14&"?body=Hello "&A14&", this is a reminder that your rent balance of "&F14&" is overdue.", "Send SMS"))
G15: =IF(A15="", "", HYPERLINK("https://wa.me/" & B15 & "?text=" & ENCODEURL("Hello " & IF(IFERROR(VLOOKUP(C15, 'Master Roster'!A:J, 10, FALSE), "")="Male", "Mr. ", "Ms. ") & A15 & ", this is a reminder that your rent balance of K" & F15 & " is due. Please make a payment,"), "Message on WhatsApp")) | H15: =IF(ISBLANK(A15), "", HYPERLINK("sms:"&B15&"?body=Hello "&A15&", this is a reminder that your rent balance of "&F15&" is overdue.", "Send SMS"))
G16: =IF(A16="", "", HYPERLINK("https://wa.me/" & B16 & "?text=" & ENCODEURL("Hello " & IF(IFERROR(VLOOKUP(C16, 'Master Roster'!A:J, 10, FALSE), "")="Male", "Mr. ", "Ms. ") & A16 & ", this is a reminder that your rent balance of K" & F16 & " is due. Please make a payment,"), "Message on WhatsApp")) | H16: =IF(ISBLANK(A16), "", HYPERLINK("sms:"&B16&"?body=Hello "&A16&", this is a reminder that your rent balance of "&F16&" is overdue.", "Send SMS"))
G17: =IF(A17="", "", HYPERLINK("https://wa.me/" & B17 & "?text=" & ENCODEURL("Hello " & IF(IFERROR(VLOOKUP(C17, 'Master Roster'!A:J, 10, FALSE), "")="Male", "Mr. ", "Ms. ") & A17 & ", this is a reminder that your rent balance of K" & F17 & " is due. Please make a payment,"), "Message on WhatsApp")) | H17: =IF(ISBLANK(A17), "", HYPERLINK("sms:"&B17&"?body=Hello "&A17&", this is a reminder that your rent balance of "&F17&" is overdue.", "Send SMS"))
G18: =IF(A18="", "", HYPERLINK("https://wa.me/" & B18 & "?text=" & ENCODEURL("Hello " & IF(IFERROR(VLOOKUP(C18, 'Master Roster'!A:J, 10, FALSE), "")="Male", "Mr. ", "Ms. ") & A18 & ", this is a reminder that your rent balance of K" & F18 & " is due. Please make a payment,"), "Message on WhatsApp")) | H18: =IF(ISBLANK(A18), "", HYPERLINK("sms:"&B18&"?body=Hello "&A18&", this is a reminder that your rent balance of "&F18&" is overdue.", "Send SMS"))
G19: =IF(A19="", "", HYPERLINK("https://wa.me/" & B19 & "?text=" & ENCODEURL("Hello " & IF(IFERROR(VLOOKUP(C19, 'Master Roster'!A:J, 10, FALSE), "")="Male", "Mr. ", "Ms. ") & A19 & ", this is a reminder that your rent balance of K" & F19 & " is due. Please make a payment,"), "Message on WhatsApp")) | H19: =IF(ISBLANK(A19), "", HYPERLINK("sms:"&B19&"?body=Hello "&A19&", this is a reminder that your rent balance of "&F19&" is overdue.", "Send SMS"))
G20: =IF(A20="", "", HYPERLINK("https://wa.me/" & B20 & "?text=" & ENCODEURL("Hello " & IF(IFERROR(VLOOKUP(C20, 'Master Roster'!A:J, 10, FALSE), "")="Male", "Mr. ", "Ms. ") & A20 & ", this is a reminder that your rent balance of K" & F20 & " is due. Please make a payment,"), "Message on WhatsApp")) | H20: =IF(ISBLANK(A20), "", HYPERLINK("sms:"&B20&"?body=Hello "&A20&", this is a reminder that your rent balance of "&F20&" is overdue.", "Send SMS"))
G21: =IF(A21="", "", HYPERLINK("https://wa.me/" & B21 & "?text=" & ENCODEURL("Hello " & IF(IFERROR(VLOOKUP(C21, 'Master Roster'!A:J, 10, FALSE), "")="Male", "Mr. ", "Ms. ") & A21 & ", this is a reminder that your rent balance of K" & F21 & " is due. Please make a payment,"), "Message on WhatsApp")) | H21: =IF(ISBLANK(A21), "", HYPERLINK("sms:"&B21&"?body=Hello "&A21&", this is a reminder that your rent balance of "&F21&" is overdue.", "Send SMS"))
G22: =IF(A22="", "", HYPERLINK("https://wa.me/" & B22 & "?text=" & ENCODEURL("Hello " & IF(IFERROR(VLOOKUP(C22, 'Master Roster'!A:J, 10, FALSE), "")="Male", "Mr. ", "Ms. ") & A22 & ", this is a reminder that your rent balance of K" & F22 & " is due. Please make a payment,"), "Message on WhatsApp")) | H22: =IF(ISBLANK(A22), "", HYPERLINK("sms:"&B22&"?body=Hello "&A22&", this is a reminder that your rent balance of "&F22&" is overdue.", "Send SMS"))
G23: =IF(A23="", "", HYPERLINK("https://wa.me/" & B23 & "?text=" & ENCODEURL("Hello " & IF(IFERROR(VLOOKUP(C23, 'Master Roster'!A:J, 10, FALSE), "")="Male", "Mr. ", "Ms. ") & A23 & ", this is a reminder that your rent balance of K" & F23 & " is due. Please make a payment,"), "Message on WhatsApp")) | H23: =IF(ISBLANK(A23), "", HYPERLINK("sms:"&B23&"?body=Hello "&A23&", this is a reminder that your rent balance of "&F23&" is overdue.", "Send SMS"))
G24: =IF(A24="", "", HYPERLINK("https://wa.me/" & B24 & "?text=" & ENCODEURL("Hello " & IF(IFERROR(VLOOKUP(C24, 'Master Roster'!A:J, 10, FALSE), "")="Male", "Mr. ", "Ms. ") & A24 & ", this is a reminder that your rent balance of K" & F24 & " is due. Please make a payment,"), "Message on WhatsApp")) | H24: =IF(ISBLANK(A24), "", HYPERLINK("sms:"&B24&"?body=Hello "&A24&", this is a reminder that your rent balance of "&F24&" is overdue.", "Send SMS"))
G25: =IF(A25="", "", HYPERLINK("https://wa.me/" & B25 & "?text=" & ENCODEURL("Hello " & IF(IFERROR(VLOOKUP(C25, 'Master Roster'!A:J, 10, FALSE), "")="Male", "Mr. ", "Ms. ") & A25 & ", this is a reminder that your rent balance of K" & F25 & " is due. Please make a payment,"), "Message on WhatsApp")) | H25: =IF(ISBLANK(A25), "", HYPERLINK("sms:"&B25&"?body=Hello "&A25&", this is a reminder that your rent balance of "&F25&" is overdue.", "Send SMS"))
... G100: =IF(A100="", "", HYPERLINK("https://wa.me/" & B100 & "?text=" & ENCODEURL("Hello " & IF(IFERROR(VLOOKUP(C100, 'Master Roster'!A:J, 10, FALSE), "")="Male", "Mr. ", "Ms. ") & A100 & ", this is a reminder that your rent balance of K" & F100 & " is due. Please make a payment,"), "Message on WhatsApp")) | H100: =IF(ISBLANK(A100), "", HYPERLINK("sms:"&B100&"?body=Hello "&A100&", this is a reminder that your rent balance of "&F100&" is overdue.", "Send SMS"))

Sheet Available Bed Spaces
A1: Available Bed Spaces | H1: Occupancy Report
A3: House/ Block | B3: Room No. | C3: Bed Space | D3: Monthly Rent | E3: Status | F3: Room Gender | H3: Gender | I3: Vacant | J3: Reserved | K3: Total
A4: =IFERROR(__xludf.DUMMYFUNCTION("IFERROR(FILTER({'Master Roster'!C4:C1006, 'Master Roster'!B4:B1006, 'Master Roster'!D4:D1006, 'Master Roster'!H4:H1006, 'Master Roster'!E4:E1006, 'Master Roster'!J4:J1006}, IF('Master Roster'!I1=""All Available"", (UPPER('Master Roster'!E4:E1006)=""VACANT"&""") + (UPPER('Master Roster'!E4:E1006)=""RESERVED""), UPPER('Master Roster'!E4:E1006)=UPPER('Master Roster'!I1))), {""No beds match the selected status"", """", """", """", """", """"})"),"BBH") -> BBH | B4: =IFERROR(__xludf.DUMMYFUNCTION("""COMPUTED_VALUE"""),7.0) -> 7 | C4: =IFERROR(__xludf.DUMMYFUNCTION("""COMPUTED_VALUE"""),"C") -> C | D4: =IFERROR(__xludf.DUMMYFUNCTION("""COMPUTED_VALUE"""),900.0) -> 900 | E4: =IFERROR(__xludf.DUMMYFUNCTION("""COMPUTED_VALUE"""),"Vacant") -> Vacant | F4: =IFERROR(__xludf.DUMMYFUNCTION("""COMPUTED_VALUE"""),"Female") -> Female | H4: Male | I4: =COUNTIFS('Master Roster'!$E$4:$E$1006, "Vacant", 'Master Roster'!$J$4:$J$1006, $H4) -> 3 | J4: =COUNTIFS('Master Roster'!$E$4:$E$1006, "Reserved", 'Master Roster'!$J$4:$J$1006, $H4) -> 0 | K4: =SUM(I4:J4) -> 3
A5: =IFERROR(__xludf.DUMMYFUNCTION("""COMPUTED_VALUE"""),"BBH") -> BBH | B5: =IFERROR(__xludf.DUMMYFUNCTION("""COMPUTED_VALUE"""),8.0) -> 8 | C5: =IFERROR(__xludf.DUMMYFUNCTION("""COMPUTED_VALUE"""),"B") -> B | D5: =IFERROR(__xludf.DUMMYFUNCTION("""COMPUTED_VALUE"""),900.0) -> 900 | E5: =IFERROR(__xludf.DUMMYFUNCTION("""COMPUTED_VALUE"""),"Vacant") -> Vacant | F5: =IFERROR(__xludf.DUMMYFUNCTION("""COMPUTED_VALUE"""),"Male") -> Male | H5: Female | I5: =COUNTIFS('Master Roster'!$E$4:$E$1006, "Vacant", 'Master Roster'!$J$4:$J$1006, $H5) -> 4 | J5: =COUNTIFS('Master Roster'!$E$4:$E$1006, "Reserved", 'Master Roster'!$J$4:$J$1006, $H5) -> 0 | K5: =SUM(I5:J5) -> 4
A6: =IFERROR(__xludf.DUMMYFUNCTION("""COMPUTED_VALUE"""),"BBH") -> BBH | B6: =IFERROR(__xludf.DUMMYFUNCTION("""COMPUTED_VALUE"""),9.0) -> 9 | C6: =IFERROR(__xludf.DUMMYFUNCTION("""COMPUTED_VALUE"""),"C") -> C | D6: =IFERROR(__xludf.DUMMYFUNCTION("""COMPUTED_VALUE"""),900.0) -> 900 | E6: =IFERROR(__xludf.DUMMYFUNCTION("""COMPUTED_VALUE"""),"Vacant") -> Vacant | F6: =IFERROR(__xludf.DUMMYFUNCTION("""COMPUTED_VALUE"""),"Female") -> Female | H6: Total | I6: =SUM(I4:I5) -> 7 | J6: =SUM(J4:J5) -> 0 | K6: =SUM(K4:K5) -> 7
A7: =IFERROR(__xludf.DUMMYFUNCTION("""COMPUTED_VALUE"""),"UPV") -> UPV | B7: =IFERROR(__xludf.DUMMYFUNCTION("""COMPUTED_VALUE"""),10.0) -> 10 | C7: =IFERROR(__xludf.DUMMYFUNCTION("""COMPUTED_VALUE"""),"D") -> D | D7: =IFERROR(__xludf.DUMMYFUNCTION("""COMPUTED_VALUE"""),900.0) -> 900 | E7: =IFERROR(__xludf.DUMMYFUNCTION("""COMPUTED_VALUE"""),"Vacant") -> Vacant | F7: =IFERROR(__xludf.DUMMYFUNCTION("""COMPUTED_VALUE"""),"Female") -> Female | H7: Bed Space Report
A8: =IFERROR(__xludf.DUMMYFUNCTION("""COMPUTED_VALUE"""),"CRV") -> CRV | B8: =IFERROR(__xludf.DUMMYFUNCTION("""COMPUTED_VALUE"""),16.0) -> 16 | C8: =IFERROR(__xludf.DUMMYFUNCTION("""COMPUTED_VALUE"""),"A") -> A | D8: =IFERROR(__xludf.DUMMYFUNCTION("""COMPUTED_VALUE"""),0.0) -> 0 | E8: =IFERROR(__xludf.DUMMYFUNCTION("""COMPUTED_VALUE"""),"Vacant") -> Vacant | F8: =IFERROR(__xludf.DUMMYFUNCTION("""COMPUTED_VALUE"""),"Male") -> Male | H8: Active Tenants | I8: =COUNTIFS('Master Roster'!E4:E1006, "<>VACANT", 'Master Roster'!E4:E1006, "<>RESERVED", 'Master Roster'!E4:E1006, "<>") -> 47
A9: =IFERROR(__xludf.DUMMYFUNCTION("""COMPUTED_VALUE"""),"NWG") -> NWG | B9: =IFERROR(__xludf.DUMMYFUNCTION("""COMPUTED_VALUE"""),22.0) -> 22 | C9: =IFERROR(__xludf.DUMMYFUNCTION("""COMPUTED_VALUE"""),"A") -> A | D9: =IFERROR(__xludf.DUMMYFUNCTION("""COMPUTED_VALUE"""),1200.0) -> 1200 | E9: =IFERROR(__xludf.DUMMYFUNCTION("""COMPUTED_VALUE"""),"Vacant") -> Vacant | F9: =IFERROR(__xludf.DUMMYFUNCTION("""COMPUTED_VALUE"""),"Male") -> Male | H9: Vacant/Reserved. | I9: =K6 -> 7
A10: =IFERROR(__xludf.DUMMYFUNCTION("""COMPUTED_VALUE"""),"NWG") -> NWG | B10: =IFERROR(__xludf.DUMMYFUNCTION("""COMPUTED_VALUE"""),23.0) -> 23 | C10: =IFERROR(__xludf.DUMMYFUNCTION("""COMPUTED_VALUE"""),"A") -> A | D10: =IFERROR(__xludf.DUMMYFUNCTION("""COMPUTED_VALUE"""),1200.0) -> 1200 | E10: =IFERROR(__xludf.DUMMYFUNCTION("""COMPUTED_VALUE"""),"Vacant") -> Vacant | F10: =IFERROR(__xludf.DUMMYFUNCTION("""COMPUTED_VALUE"""),"Female") -> Female | H10: Total Bed Spaces | I10: =I8+I9 -> 54
H11: Expeted Revenue | I11: =SUMIFS('Master Roster'!H4:H1006, 'Master Roster'!E4:E1006, "<>Vacant") -> 50250
H12: Full Capacity Revenue | I12: =SUM('Master Roster'!H:H) -> 56250
H13: Days 20-30 | I13: {=SUM(IF(ISNUMBER('Master Roster'!G4:G1006), IF((DAY('Master Roster'!G4:G1006)>=20)*(DAY('Master Roster'!G4:G1006)<=31), 'Master Roster'!H4:H1006, 0), 0))} -> 12400
H14: Days 1-5 | I14: {=SUM(IF(ISNUMBER('Master Roster'!G4:G1006), IF((DAY('Master Roster'!G4:G1006)>=1)*(DAY('Master Roster'!G4:G1006)<=5), 'Master Roster'!H4:H1006, 0), 0))} -> 18800 | J14: =I13+I14 -> 31200
H15: Days 1-5 Total | I15: =SUM(I17:I1006) -> 29500 | L15: Days 20-30 Total | M15: =SUM(M17:M1006) -> 20300
H16: Tenant Name | I16: Amount | J16: Entry Date | L16: Tenant Name | M16: Amount | N16: Entry Date
H17: =IFERROR(__xludf.DUMMYFUNCTION("IFERROR(ARRAYFORMULA(LET(names, 'Master Roster'!E4:E1006, base_amounts, 'Master Roster'!H4:H1006, dates, 'Master Roster'!G4:G1006, day_val, IF(dates="""", 0, IF(ISNUMBER(dates), DAY(dates), IFERROR(VALUE(LEFT(dates, FIND(""/"", dates)-1)), 0))), balances,"&" IFERROR(VLOOKUP(names, {'Monthly Billing Tab'!D4:D1006, 'Monthly Billing Tab'!L4:L1006}, 2, FALSE), 0), valid, (names<>"""") * (base_amounts<>"""") * (balances<>0), mask2, (day_val>=1)*(day_val<=5), keep, valid * mask2, SORT(FILTER({names, base_amounts, "&"dates}, keep), 3, TRUE))), ""No tenants found"")"),"Gabirel Kabwe") -> Gabirel Kabwe | I17: =IFERROR(__xludf.DUMMYFUNCTION("""COMPUTED_VALUE"""),1200.0) -> 1200 | J17: =IFERROR(__xludf.DUMMYFUNCTION("""COMPUTED_VALUE"""),46143.0) -> 46143 | L17: =IFERROR(__xludf.DUMMYFUNCTION("IFERROR(ARRAYFORMULA(LET(names, 'Master Roster'!E4:E1006, base_amounts, 'Master Roster'!H4:H1006, dates, 'Master Roster'!G4:G1006, day_val, IF(dates="""", 0, IF(ISNUMBER(dates), DAY(dates), IFERROR(VALUE(LEFT(dates, FIND(""/"", dates)-1)), 0))), balances,"&" IFERROR(VLOOKUP(names, {'Monthly Billing Tab'!D4:D1006, 'Monthly Billing Tab'!L4:L1006}, 2, FALSE), 0), valid, (names<>"""") * (base_amounts<>"""") * (balances<>0), mask2, (day_val>=20)*(day_val<=31), keep, valid * mask2, SORT(FILTER({names, base_amounts"&", dates}, keep), 3, TRUE))), ""No tenants found"")"),"Nanga Obrien") -> Nanga Obrien | M17: =IFERROR(__xludf.DUMMYFUNCTION("""COMPUTED_VALUE"""),900.0) -> 900 | N17: =IFERROR(__xludf.DUMMYFUNCTION("""COMPUTED_VALUE"""),46048.0) -> 46048
H18: =IFERROR(__xludf.DUMMYFUNCTION("""COMPUTED_VALUE"""),"McDonald") -> McDonald | I18: =IFERROR(__xludf.DUMMYFUNCTION("""COMPUTED_VALUE"""),900.0) -> 900 | J18: =IFERROR(__xludf.DUMMYFUNCTION("""COMPUTED_VALUE"""),46174.0) -> 46174 | L18: =IFERROR(__xludf.DUMMYFUNCTION("""COMPUTED_VALUE"""),"Lushomo gambwe") -> Lushomo gambwe | M18: =IFERROR(__xludf.DUMMYFUNCTION("""COMPUTED_VALUE"""),1200.0) -> 1200 | N18: =IFERROR(__xludf.DUMMYFUNCTION("""COMPUTED_VALUE"""),46078.0) -> 46078
H19: =IFERROR(__xludf.DUMMYFUNCTION("""COMPUTED_VALUE"""),"Collins Mubanga") -> Collins Mubanga | I19: =IFERROR(__xludf.DUMMYFUNCTION("""COMPUTED_VALUE"""),900.0) -> 900 | J19: =IFERROR(__xludf.DUMMYFUNCTION("""COMPUTED_VALUE"""),46176.0) -> 46176 | L19: =IFERROR(__xludf.DUMMYFUNCTION("""COMPUTED_VALUE"""),"Himalikiti Saviour") -> Himalikiti Saviour | M19: =IFERROR(__xludf.DUMMYFUNCTION("""COMPUTED_VALUE"""),950.0) -> 950 | N19: =IFERROR(__xludf.DUMMYFUNCTION("""COMPUTED_VALUE"""),46195.0) -> 46195
H20: =IFERROR(__xludf.DUMMYFUNCTION("""COMPUTED_VALUE"""),"Harriet nanyangwe") -> Harriet nanyangwe | I20: =IFERROR(__xludf.DUMMYFUNCTION("""COMPUTED_VALUE"""),1100.0) -> 1100 | J20: =IFERROR(__xludf.DUMMYFUNCTION("""COMPUTED_VALUE"""),46176.0) -> 46176 | L20: =IFERROR(__xludf.DUMMYFUNCTION("""COMPUTED_VALUE"""),"Kangwa Kunda") -> Kangwa Kunda | M20: =IFERROR(__xludf.DUMMYFUNCTION("""COMPUTED_VALUE"""),900.0) -> 900 | N20: =IFERROR(__xludf.DUMMYFUNCTION("""COMPUTED_VALUE"""),46198.0) -> 46198
H21: =IFERROR(__xludf.DUMMYFUNCTION("""COMPUTED_VALUE"""),"Wisdom Bwani") -> Wisdom Bwani | I21: =IFERROR(__xludf.DUMMYFUNCTION("""COMPUTED_VALUE"""),900.0) -> 900 | J21: =IFERROR(__xludf.DUMMYFUNCTION("""COMPUTED_VALUE"""),46178.0) -> 46178 | L21: =IFERROR(__xludf.DUMMYFUNCTION("""COMPUTED_VALUE"""),"Sara Matakala") -> Sara Matakala | M21: =IFERROR(__xludf.DUMMYFUNCTION("""COMPUTED_VALUE"""),900.0) -> 900 | N21: =IFERROR(__xludf.DUMMYFUNCTION("""COMPUTED_VALUE"""),46198.0) -> 46198
H22: =IFERROR(__xludf.DUMMYFUNCTION("""COMPUTED_VALUE"""),"Funny Muyamina") -> Funny Muyamina | I22: =IFERROR(__xludf.DUMMYFUNCTION("""COMPUTED_VALUE"""),900.0) -> 900 | J22: =IFERROR(__xludf.DUMMYFUNCTION("""COMPUTED_VALUE"""),46178.0) -> 46178 | L22: =IFERROR(__xludf.DUMMYFUNCTION("""COMPUTED_VALUE"""),"Samantha Musako (Kakompe)") -> Samantha Musako (Kakompe) | M22: =IFERROR(__xludf.DUMMYFUNCTION("""COMPUTED_VALUE"""),1200.0) -> 1200 | N22: =IFERROR(__xludf.DUMMYFUNCTION("""COMPUTED_VALUE"""),46199.0) -> 46199
H23: =IFERROR(__xludf.DUMMYFUNCTION("""COMPUTED_VALUE"""),"Treasure Simeenda") -> Treasure Simeenda | I23: =IFERROR(__xludf.DUMMYFUNCTION("""COMPUTED_VALUE"""),900.0) -> 900 | J23: =IFERROR(__xludf.DUMMYFUNCTION("""COMPUTED_VALUE"""),46178.0) -> 46178 | L23: =IFERROR(__xludf.DUMMYFUNCTION("""COMPUTED_VALUE"""),"Wendy Mpakise") -> Wendy Mpakise | M23: =IFERROR(__xludf.DUMMYFUNCTION("""COMPUTED_VALUE"""),900.0) -> 900 | N23: =IFERROR(__xludf.DUMMYFUNCTION("""COMPUTED_VALUE"""),46200.0) -> 46200
L24: =IFERROR(__xludf.DUMMYFUNCTION("""COMPUTED_VALUE"""),"Adrian mulale") -> Adrian mulale | M24: =IFERROR(__xludf.DUMMYFUNCTION("""COMPUTED_VALUE"""),950.0) -> 950 | N24: =IFERROR(__xludf.DUMMYFUNCTION("""COMPUTED_VALUE"""),46203.0) -> 46203
L25: =IFERROR(__xludf.DUMMYFUNCTION("""COMPUTED_VALUE"""),"Ackim Siamafuko") -> Ackim Siamafuko | M25: =IFERROR(__xludf.DUMMYFUNCTION("""COMPUTED_VALUE"""),1200.0) -> 1200 | N25: =IFERROR(__xludf.DUMMYFUNCTION("""COMPUTED_VALUE"""),46223.0) -> 46223
L26: =IFERROR(__xludf.DUMMYFUNCTION("""COMPUTED_VALUE"""),"Shadrach Munganini") -> Shadrach Munganini | M26: =IFERROR(__xludf.DUMMYFUNCTION("""COMPUTED_VALUE"""),900.0) -> 900 | N26: =IFERROR(__xludf.DUMMYFUNCTION("""COMPUTED_VALUE"""),46228.0) -> 46228
L27: =IFERROR(__xludf.DUMMYFUNCTION("""COMPUTED_VALUE"""),"Kuwunda Makondo") -> Kuwunda Makondo | M27: =IFERROR(__xludf.DUMMYFUNCTION("""COMPUTED_VALUE"""),1200.0) -> 1200 | N27: =IFERROR(__xludf.DUMMYFUNCTION("""COMPUTED_VALUE"""),46263.0) -> 46263
H30: TOTAL | I30: =SUM(I17:I25) -> 6800 | L30: TOTAL | M30: =SUM(M17:M25) -> 9100
H32: GRAND TOTAL | I32: =I30+M30 -> 15900

Sheet Monthly Billing Tab
A1: Monthly Billing Tab
C2: Search Tenant: | D2: Emely Mwale
A3: No. | B3: Billing ID | C3: House/Block | D3: Tenant Name | E3: Phone Number | F3: Current Rent | G3: Entry Date | H3: Adjustments / Fees | I3: Adjustment Notes | J3: Target Month | K3: {={"Accumulated Total"; IFERROR(IF(F4:F999="","", IF(J4:J999="","", F4:F999 * MONTH(J4:J999 & " 1"))), "")}} -> Accumulated Total | L3: {={"Total Balance"; IFERROR(IF(B4:B999="", "", IF((D4:D999="Vacant")+(D4:D999="Reserved"), 0, IF(((MONTH(TODAY())*F4:F999)+N(H4:H999)-K4:K999) < 0, 0, (MONTH(TODAY())*F4:F999)+N(H4:H999)-K4:K999))), "")}} -> Total Balance | M3: {={"Billing Status"; IF(D4:D999="", "", IF(D4:D999="Vacant", "Vacant", IF(L4:L999<=0, "✅ Paid / Secured", IF((L4:L999>F4:F999) + (TODAY() > DATE(YEAR(TODAY()), MONTH(TODAY()), DAY(G4:G999)) + 5), "❌ OVERDUE / UNPAID", IF(TODAY() >= DATE(YEAR(TODAY()), MONTH(TODAY()), DAY(G4:G999)), "⏳ Grace Period", "🟢 Open Window")))))}} -> Billing Status
A4: {=SEQUENCE(COUNTA(B4:B999),1)} -> 1 | B4: ANX-19-A | C4: =IFERROR(VLOOKUP($B4, 'Master Roster'!$A:$C, 3, FALSE), "") -> ANX | D4: =IFERROR(VLOOKUP($B4, 'Master Roster'!$A:$E, 5, FALSE), "") -> Samantha Musako (Kakompe) | E4: =IFERROR(VLOOKUP($B4, 'Master Roster'!$A:$F, 6, FALSE), "") -> 260977227794 | F4: =IFERROR(VLOOKUP($B4, 'Master Roster'!$A:$H, 8, FALSE), "") -> 1200 | G4: =IFERROR(VLOOKUP($B4, 'Master Roster'!$A:$G, 7, FALSE), "") -> 46199 | J4: Aug | K4: 9600 | L4: 1200 | M4: 🟢 Open Window
A5: 2 | B5: ANX-19-B | C5: =IFERROR(VLOOKUP($B5, 'Master Roster'!$A:$C, 3, FALSE), "") -> ANX | D5: =IFERROR(VLOOKUP($B5, 'Master Roster'!$A:$E, 5, FALSE), "") -> Chanda Lutashima | E5: =IFERROR(VLOOKUP($B5, 'Master Roster'!$A:$F, 6, FALSE), "") -> 260977951894 | F5: =IFERROR(VLOOKUP($B5, 'Master Roster'!$A:$H, 8, FALSE), "") -> 1200 | G5: =IFERROR(VLOOKUP($B5, 'Master Roster'!$A:$G, 7, FALSE), "") -> 46180 | J5: Sep | K5: 10800 | L5: 0 | M5: ✅ Paid / Secured
A6: 3 | B6: ANX-19-C | C6: =IFERROR(VLOOKUP($B6, 'Master Roster'!$A:$C, 3, FALSE), "") -> ANX | D6: =IFERROR(VLOOKUP($B6, 'Master Roster'!$A:$E, 5, FALSE), "") -> Josephine Nyirenda | E6: =IFERROR(VLOOKUP($B6, 'Master Roster'!$A:$F, 6, FALSE), "") -> 260779841908 | F6: =IFERROR(VLOOKUP($B6, 'Master Roster'!$A:$H, 8, FALSE), "") -> 1200 | G6: =IFERROR(VLOOKUP($B6, 'Master Roster'!$A:$G, 7, FALSE), "") -> 46148 | J6: Aug | K6: 9600 | L6: 1200 | M6: ⏳ Grace Period
A7: 4 | B7: ANX-19-D | C7: =IFERROR(VLOOKUP($B7, 'Master Roster'!$A:$C, 3, FALSE), "") -> ANX | D7: =IFERROR(VLOOKUP($B7, 'Master Roster'!$A:$E, 5, FALSE), "") -> Lubono Ruthendo | E7: =IFERROR(VLOOKUP($B7, 'Master Roster'!$A:$F, 6, FALSE), "") -> 260953618278 | F7: =IFERROR(VLOOKUP($B7, 'Master Roster'!$A:$H, 8, FALSE), "") -> 1200 | G7: =IFERROR(VLOOKUP($B7, 'Master Roster'!$A:$G, 7, FALSE), "") -> 46207 | J7: Sep | K7: 10800 | L7: 0 | M7: ✅ Paid / Secured
A8: 5 | B8: ANX-20-A | C8: =IFERROR(VLOOKUP($B8, 'Master Roster'!$A:$C, 3, FALSE), "") -> ANX | D8: =IFERROR(VLOOKUP($B8, 'Master Roster'!$A:$E, 5, FALSE), "") -> Steven Musonda | E8: =IFERROR(VLOOKUP($B8, 'Master Roster'!$A:$F, 6, FALSE), "") -> 260975303236 | F8: =IFERROR(VLOOKUP($B8, 'Master Roster'!$A:$H, 8, FALSE), "") -> 1400 | G8: =IFERROR(VLOOKUP($B8, 'Master Roster'!$A:$G, 7, FALSE), "") -> 46178 | J8: Sep | K8: 12600 | L8: 0 | M8: ✅ Paid / Secured
A9: 6 | B9: BBH-1-A | C9: =IFERROR(VLOOKUP($B9, 'Master Roster'!$A:$C, 3, FALSE), "") -> BBH | D9: =IFERROR(VLOOKUP($B9, 'Master Roster'!$A:$E, 5, FALSE), "") -> Adrian mulale | E9: =IFERROR(VLOOKUP($B9, 'Master Roster'!$A:$F, 6, FALSE), "") -> 260977146630 | F9: =IFERROR(VLOOKUP($B9, 'Master Roster'!$A:$H, 8, FALSE), "") -> 950 | G9: =IFERROR(VLOOKUP($B9, 'Master Roster'!$A:$G, 7, FALSE), "") -> 46203 | J9: Aug | K9: 7600 | L9: 950 | M9: 🟢 Open Window
A10: 7 | B10: BBH-2-A | C10: =IFERROR(VLOOKUP($B10, 'Master Roster'!$A:$C, 3, FALSE), "") -> BBH | D10: =IFERROR(VLOOKUP($B10, 'Master Roster'!$A:$E, 5, FALSE), "") -> Wisdom Bwani | E10: =IFERROR(VLOOKUP($B10, 'Master Roster'!$A:$F, 6, FALSE), "") -> 260776960320 | F10: =IFERROR(VLOOKUP($B10, 'Master Roster'!$A:$H, 8, FALSE), "") -> 900 | G10: =IFERROR(VLOOKUP($B10, 'Master Roster'!$A:$G, 7, FALSE), "") -> 46178 | J10: Aug | K10: 7200 | L10: 900 | M10: ⏳ Grace Period
A11: 8 | B11: BBH-2-B | C11: =IFERROR(VLOOKUP($B11, 'Master Roster'!$A:$C, 3, FALSE), "") -> BBH | D11: =IFERROR(VLOOKUP($B11, 'Master Roster'!$A:$E, 5, FALSE), "") -> Jackson Mwanza | E11: =IFERROR(VLOOKUP($B11, 'Master Roster'!$A:$F, 6, FALSE), "") -> 260976625656 | F11: =IFERROR(VLOOKUP($B11, 'Master Roster'!$A:$H, 8, FALSE), "") -> 900 | G11: =IFERROR(VLOOKUP($B11, 'Master Roster'!$A:$G, 7, FALSE), "") -> 46181 | H11: -600 | J11: Jul | K11: 6300 | L11: 1200 | M11: ❌ OVERDUE / UNPAID
A12: 9 | B12: BBH-3-A | C12: =IFERROR(VLOOKUP($B12, 'Master Roster'!$A:$C, 3, FALSE), "") -> BBH | D12: =IFERROR(VLOOKUP($B12, 'Master Roster'!$A:$E, 5, FALSE), "") -> Prosper Kalayi | E12: =IFERROR(VLOOKUP($B12, 'Master Roster'!$A:$F, 6, FALSE), "") -> 260970522913 | F12: =IFERROR(VLOOKUP($B12, 'Master Roster'!$A:$H, 8, FALSE), "") -> 900 | G12: =IFERROR(VLOOKUP($B12, 'Master Roster'!$A:$G, 7, FALSE), "") -> 46186 | J12: Aug | K12: 7200 | L12: 900 | M12: 🟢 Open Window
A13: 10 | B13: BBH-3-B | C13: =IFERROR(VLOOKUP($B13, 'Master Roster'!$A:$C, 3, FALSE), "") -> BBH | D13: =IFERROR(VLOOKUP($B13, 'Master Roster'!$A:$E, 5, FALSE), "") -> Shadrach Munganini | E13: =IFERROR(VLOOKUP($B13, 'Master Roster'!$A:$F, 6, FALSE), "") -> 260979567550 | F13: =IFERROR(VLOOKUP($B13, 'Master Roster'!$A:$H, 8, FALSE), "") -> 900 | G13: =IFERROR(VLOOKUP($B13, 'Master Roster'!$A:$G, 7, FALSE), "") -> 46228 | J13: Aug | K13: 7200 | L13: 900 | M13: 🟢 Open Window
A14: 11 | B14: BBH-3-C | C14: =IFERROR(VLOOKUP($B14, 'Master Roster'!$A:$C, 3, FALSE), "") -> BBH | D14: =IFERROR(VLOOKUP($B14, 'Master Roster'!$A:$E, 5, FALSE), "") -> Collins Mubanga | E14: =IFERROR(VLOOKUP($B14, 'Master Roster'!$A:$F, 6, FALSE), "") -> 260777237029 | F14: =IFERROR(VLOOKUP($B14, 'Master Roster'!$A:$H, 8, FALSE), "") -> 900 | G14: =IFERROR(VLOOKUP($B14, 'Master Roster'!$A:$G, 7, FALSE), "") -> 46176 | J14: Aug | K14: 7200 | L14: 900 | M14: ⏳ Grace Period
A15: 12 | B15: BBH-4-A | C15: =IFERROR(VLOOKUP($B15, 'Master Roster'!$A:$C, 3, FALSE), "") -> BBH | D15: =IFERROR(VLOOKUP($B15, 'Master Roster'!$A:$E, 5, FALSE), "") -> Himalikiti Saviour | E15: =IFERROR(VLOOKUP($B15, 'Master Roster'!$A:$F, 6, FALSE), "") -> 260975547126 | F15: =IFERROR(VLOOKUP($B15, 'Master Roster'!$A:$H, 8, FALSE), "") -> 950 | G15: =IFERROR(VLOOKUP($B15, 'Master Roster'!$A:$G, 7, FALSE), "") -> 46195 | J15: Jul | K15: 6650 | L15: 1900 | M15: ❌ OVERDUE / UNPAID
A16: 13 | B16: BBH-5-A | C16: =IFERROR(VLOOKUP($B16, 'Master Roster'!$A:$C, 3, FALSE), "") -> BBH | D16: =IFERROR(VLOOKUP($B16, 'Master Roster'!$A:$E, 5, FALSE), "") -> Wampa | E16: =IFERROR(VLOOKUP($B16, 'Master Roster'!$A:$F, 6, FALSE), "") -> 260971071877 | F16: =IFERROR(VLOOKUP($B16, 'Master Roster'!$A:$H, 8, FALSE), "") -> 0 | G16: =IFERROR(VLOOKUP($B16, 'Master Roster'!$A:$G, 7, FALSE), "") -> 46225 | I16: Excluded - Wampa | J16: Jul | K16: 0 | L16: 0 | M16: ✅ Paid / Secured
A17: 14 | B17: BBH-6-A | C17: =IFERROR(VLOOKUP($B17, 'Master Roster'!$A:$C, 3, FALSE), "") -> BBH | D17: =IFERROR(VLOOKUP($B17, 'Master Roster'!$A:$E, 5, FALSE), "") -> McDonald | E17: =IFERROR(VLOOKUP($B17, 'Master Roster'!$A:$F, 6, FALSE), "") -> 260773456119 | F17: =IFERROR(VLOOKUP($B17, 'Master Roster'!$A:$H, 8, FALSE), "") -> 900 | G17: =IFERROR(VLOOKUP($B17, 'Master Roster'!$A:$G, 7, FALSE), "") -> 46174 | H17: -1000 | I17: Part Payment | J17: May | K17: 4500 | L17: 2600 | M17: ❌ OVERDUE / UNPAID
A18: 15 | B18: BBH-6-B | C18: =IFERROR(VLOOKUP($B18, 'Master Roster'!$A:$C, 3, FALSE), "") -> BBH | D18: =IFERROR(VLOOKUP($B18, 'Master Roster'!$A:$E, 5, FALSE), "") -> Nanga Obrien | E18: =IFERROR(VLOOKUP($B18, 'Master Roster'!$A:$F, 6, FALSE), "") -> 260770838758 | F18: =IFERROR(VLOOKUP($B18, 'Master Roster'!$A:$H, 8, FALSE), "") -> 900 | G18: =IFERROR(VLOOKUP($B18, 'Master Roster'!$A:$G, 7, FALSE), "") -> 46048 | J18: May | K18: 4500 | L18: 3600 | M18: ❌ OVERDUE / UNPAID
A19: 16 | B19: BBH-6-C | C19: =IFERROR(VLOOKUP($B19, 'Master Roster'!$A:$C, 3, FALSE), "") -> BBH | D19: =IFERROR(VLOOKUP($B19, 'Master Roster'!$A:$E, 5, FALSE), "") -> Zick Phiri | E19: =IFERROR(VLOOKUP($B19, 'Master Roster'!$A:$F, 6, FALSE), "") -> 260973072762 | F19: =IFERROR(VLOOKUP($B19, 'Master Roster'!$A:$H, 8, FALSE), "") -> 900 | G19: =IFERROR(VLOOKUP($B19, 'Master Roster'!$A:$G, 7, FALSE), "") -> 46184 | J19: Aug | K19: 7200 | L19: 900 | M19: 🟢 Open Window
A20: 17 | B20: BBH-7-A | C20: =IFERROR(VLOOKUP($B20, 'Master Roster'!$A:$C, 3, FALSE), "") -> BBH | D20: =IFERROR(VLOOKUP($B20, 'Master Roster'!$A:$E, 5, FALSE), "") -> Funny Muyamina | E20: =IFERROR(VLOOKUP($B20, 'Master Roster'!$A:$F, 6, FALSE), "") -> 260771096585 | F20: =IFERROR(VLOOKUP($B20, 'Master Roster'!$A:$H, 8, FALSE), "") -> 900 | G20: =IFERROR(VLOOKUP($B20, 'Master Roster'!$A:$G, 7, FALSE), "") -> 46178 | J20: Aug | K20: 7200 | L20: 900 | M20: ⏳ Grace Period
A21: 18 | B21: BBH-7-B | C21: =IFERROR(VLOOKUP($B21, 'Master Roster'!$A:$C, 3, FALSE), "") -> BBH | D21: =IFERROR(VLOOKUP($B21, 'Master Roster'!$A:$E, 5, FALSE), "") -> Treasure Simeenda | E21: =IFERROR(VLOOKUP($B21, 'Master Roster'!$A:$F, 6, FALSE), "") -> 260772393278 | F21: =IFERROR(VLOOKUP($B21, 'Master Roster'!$A:$H, 8, FALSE), "") -> 900 | G21: =IFERROR(VLOOKUP($B21, 'Master Roster'!$A:$G, 7, FALSE), "") -> 46178 | J21: Aug | K21: 7200 | L21: 900 | M21: ⏳ Grace Period
A22: 19 | B22: BBH-7-C | C22: =IFERROR(VLOOKUP($B22, 'Master Roster'!$A:$C, 3, FALSE), "") -> BBH | D22: =IFERROR(VLOOKUP($B22, 'Master Roster'!$A:$E, 5, FALSE), "") -> Vacant | E22: =IFERROR(VLOOKUP($B22, 'Master Roster'!$A:$F, 6, FALSE), "") | F22: =IFERROR(VLOOKUP($B22, 'Master Roster'!$A:$H, 8, FALSE), "") -> 900 | G22: =IFERROR(VLOOKUP($B22, 'Master Roster'!$A:$G, 7, FALSE), "") | J22: Jun | K22: 5400 | L22: 0 | M22: Vacant
A23: 20 | B23: BBH-8-A | C23: =IFERROR(VLOOKUP($B23, 'Master Roster'!$A:$C, 3, FALSE), "") -> BBH | D23: =IFERROR(VLOOKUP($B23, 'Master Roster'!$A:$E, 5, FALSE), "") -> Kangwa Kunda | E23: =IFERROR(VLOOKUP($B23, 'Master Roster'!$A:$F, 6, FALSE), "") -> 260972024337 | F23: =IFERROR(VLOOKUP($B23, 'Master Roster'!$A:$H, 8, FALSE), "") -> 900 | G23: =IFERROR(VLOOKUP($B23, 'Master Roster'!$A:$G, 7, FALSE), "") -> 46198 | J23: Aug | K23: 7200 | L23: 900 | M23: 🟢 Open Window
A24: 21 | B24: BBH-8-B | C24: =IFERROR(VLOOKUP($B24, 'Master Roster'!$A:$C, 3, FALSE), "") -> BBH | D24: =IFERROR(VLOOKUP($B24, 'Master Roster'!$A:$E, 5, FALSE), "") -> Vacant | E24: =IFERROR(VLOOKUP($B24, 'Master Roster'!$A:$F, 6, FALSE), "") | F24: =IFERROR(VLOOKUP($B24, 'Master Roster'!$A:$H, 8, FALSE), "") -> 900 | G24: =IFERROR(VLOOKUP($B24, 'Master Roster'!$A:$G, 7, FALSE), "") | J24: Jun | K24: 5400 | L24: 0 | M24: Vacant
A25: 22 | B25: BBH-9-A | C25: =IFERROR(VLOOKUP($B25, 'Master Roster'!$A:$C, 3, FALSE), "") -> BBH | D25: =IFERROR(VLOOKUP($B25, 'Master Roster'!$A:$E, 5, FALSE), "") -> Felistus Mweemba | E25: =IFERROR(VLOOKUP($B25, 'Master Roster'!$A:$F, 6, FALSE), "") -> 260764785030 | F25: =IFERROR(VLOOKUP($B25, 'Master Roster'!$A:$H, 8, FALSE), "") -> 900 | G25: =IFERROR(VLOOKUP($B25, 'Master Roster'!$A:$G, 7, FALSE), "") -> 46182 | J25: Aug | K25: 7200 | L25: 900 | M25: 🟢 Open Window
A26: 23 | B26: BBH-9-B | C26: =IFERROR(VLOOKUP($B26, 'Master Roster'!$A:$C, 3, FALSE), "") -> BBH | D26: =IFERROR(VLOOKUP($B26, 'Master Roster'!$A:$E, 5, FALSE), "") -> Wendy Mpakise | E26: =IFERROR(VLOOKUP($B26, 'Master Roster'!$A:$F, 6, FALSE), "") -> 260971977845 | F26: =IFERROR(VLOOKUP($B26, 'Master Roster'!$A:$H, 8, FALSE), "") -> 900 | G26: =IFERROR(VLOOKUP($B26, 'Master Roster'!$A:$G, 7, FALSE), "") -> 46200 | J26: Jul | K26: 6300 | L26: 1800 | M26: ❌ OVERDUE / UNPAID
A27: 24 | B27: BBH-9-C | C27: =IFERROR(VLOOKUP($B27, 'Master Roster'!$A:$C, 3, FALSE), "") -> BBH | D27: =IFERROR(VLOOKUP($B27, 'Master Roster'!$A:$E, 5, FALSE), "") -> Vacant | E27: =IFERROR(VLOOKUP($B27, 'Master Roster'!$A:$F, 6, FALSE), "") | F27: =IFERROR(VLOOKUP($B27, 'Master Roster'!$A:$H, 8, FALSE), "") -> 900 | G27: =IFERROR(VLOOKUP($B27, 'Master Roster'!$A:$G, 7, FALSE), "") | J27: Jul | K27: 6300 | L27: 0 | M27: Vacant
A28: 25 | B28: CRV-16-A | C28: =IFERROR(VLOOKUP($B28, 'Master Roster'!$A:$C, 3, FALSE), "") -> CRV | D28: =IFERROR(VLOOKUP($B28, 'Master Roster'!$A:$E, 5, FALSE), "") -> Vacant | E28: =IFERROR(VLOOKUP($B28, 'Master Roster'!$A:$F, 6, FALSE), "") -> 20772046008 | F28: =IFERROR(VLOOKUP($B28, 'Master Roster'!$A:$H, 8, FALSE), "") -> 0 | G28: =IFERROR(VLOOKUP($B28, 'Master Roster'!$A:$G, 7, FALSE), "") -> 46223 | J28: Aug | K28: 0 | L28: 0 | M28: Vacant
A29: 26 | B29: CRV-16-B | C29: =IFERROR(VLOOKUP($B29, 'Master Roster'!$A:$C, 3, FALSE), "") -> CRV | D29: =IFERROR(VLOOKUP($B29, 'Master Roster'!$A:$E, 5, FALSE), "") -> Ackim Siamafuko | E29: =IFERROR(VLOOKUP($B29, 'Master Roster'!$A:$F, 6, FALSE), "") -> 20772046008 | F29: =IFERROR(VLOOKUP($B29, 'Master Roster'!$A:$H, 8, FALSE), "") -> 1200 | G29: =IFERROR(VLOOKUP($B29, 'Master Roster'!$A:$G, 7, FALSE), "") -> 46223 | J29: Aug | K29: 9600 | L29: 1200 | M29: 🟢 Open Window
... A31: 28 | B31: CRV-18-A | C31: =IFERROR(VLOOKUP($B31, 'Master Roster'!$A:$C, 3, FALSE), "") -> CRV | D31: =IFERROR(VLOOKUP($B31, 'Master Roster'!$A:$E, 5, FALSE), "") -> Christopher Tambule | E31: =IFERROR(VLOOKUP($B31, 'Master Roster'!$A:$F, 6, FALSE), "") -> 260972108866 | F31: =IFERROR(VLOOKUP($B31, 'Master Roster'!$A:$H, 8, FALSE), "") -> 1200 | G31: =IFERROR(VLOOKUP($B31, 'Master Roster'!$A:$G, 7, FALSE), "") -> 46190 | J31: Aug | K31: 9600 | L31: 1200 | M31: 🟢 Open Window
A32: 29 | B32: NWG-21-A | C32: =IFERROR(VLOOKUP($B32, 'Master Roster'!$A:$C, 3, FALSE), "") -> NWG | D32: =IFERROR(VLOOKUP($B32, 'Master Roster'!$A:$E, 5, FALSE), "") -> Lukundo Siame | E32: =IFERROR(VLOOKUP($B32, 'Master Roster'!$A:$F, 6, FALSE), "") -> 260760833629 | F32: =IFERROR(VLOOKUP($B32, 'Master Roster'!$A:$H, 8, FALSE), "") -> 1200 | G32: =IFERROR(VLOOKUP($B32, 'Master Roster'!$A:$G, 7, FALSE), "") -> 46191 | H32: -1150 | J32: Jul | K32: 8400 | L32: 1250 | M32: ❌ OVERDUE / UNPAID
A33: 30 | B33: NWG-21-B | C33: =IFERROR(VLOOKUP($B33, 'Master Roster'!$A:$C, 3, FALSE), "") -> NWG | D33: =IFERROR(VLOOKUP($B33, 'Master Roster'!$A:$E, 5, FALSE), "") -> Gabirel Kabwe | E33: =IFERROR(VLOOKUP($B33, 'Master Roster'!$A:$F, 6, FALSE), "") -> 260968723095 | F33: =IFERROR(VLOOKUP($B33, 'Master Roster'!$A:$H, 8, FALSE), "") -> 1200 | G33: =IFERROR(VLOOKUP($B33, 'Master Roster'!$A:$G, 7, FALSE), "") -> 46143 | J33: Aug | K33: 9600 | L33: 1200 | M33: ❌ OVERDUE / UNPAID
A34: 31 | B34: NWG-21-C | C34: =IFERROR(VLOOKUP($B34, 'Master Roster'!$A:$C, 3, FALSE), "") -> NWG | D34: =IFERROR(VLOOKUP($B34, 'Master Roster'!$A:$E, 5, FALSE), "") -> Chama Kampamba | E34: =IFERROR(VLOOKUP($B34, 'Master Roster'!$A:$F, 6, FALSE), "") -> 260770055753 | F34: =IFERROR(VLOOKUP($B34, 'Master Roster'!$A:$H, 8, FALSE), "") -> 1200 | G34: =IFERROR(VLOOKUP($B34, 'Master Roster'!$A:$G, 7, FALSE), "") -> 46179 | J34: Jul | K34: 8400 | L34: 2400 | M34: ❌ OVERDUE / UNPAID
A35: 32 | B35: NWG-21-D | C35: =IFERROR(VLOOKUP($B35, 'Master Roster'!$A:$C, 3, FALSE), "") -> NWG | D35: =IFERROR(VLOOKUP($B35, 'Master Roster'!$A:$E, 5, FALSE), "") -> Jairos Banda | E35: =IFERROR(VLOOKUP($B35, 'Master Roster'!$A:$F, 6, FALSE), "") -> 260776136398 | F35: =IFERROR(VLOOKUP($B35, 'Master Roster'!$A:$H, 8, FALSE), "") -> 1200 | G35: =IFERROR(VLOOKUP($B35, 'Master Roster'!$A:$G, 7, FALSE), "") -> 46174 | J35: Sep | K35: 10800 | L35: 0 | M35: ✅ Paid / Secured
A36: 33 | B36: NWG-22-A | C36: =IFERROR(VLOOKUP($B36, 'Master Roster'!$A:$C, 3, FALSE), "") -> NWG | D36: =IFERROR(VLOOKUP($B36, 'Master Roster'!$A:$E, 5, FALSE), "") -> Vacant | E36: =IFERROR(VLOOKUP($B36, 'Master Roster'!$A:$F, 6, FALSE), "") | F36: =IFERROR(VLOOKUP($B36, 'Master Roster'!$A:$H, 8, FALSE), "") -> 1200 | G36: =IFERROR(VLOOKUP($B36, 'Master Roster'!$A:$G, 7, FALSE), "") | J36: Jun | K36: 7200 | L36: 0 | M36: Vacant
A37: 34 | B37: NWG-22-B | C37: =IFERROR(VLOOKUP($B37, 'Master Roster'!$A:$C, 3, FALSE), "") -> NWG | D37: =IFERROR(VLOOKUP($B37, 'Master Roster'!$A:$E, 5, FALSE), "") -> David Mulila | E37: =IFERROR(VLOOKUP($B37, 'Master Roster'!$A:$F, 6, FALSE), "") -> 260775161085 | F37: =IFERROR(VLOOKUP($B37, 'Master Roster'!$A:$H, 8, FALSE), "") -> 1200 | G37: =IFERROR(VLOOKUP($B37, 'Master Roster'!$A:$G, 7, FALSE), "") -> 46191 | J37: Aug | K37: 9600 | L37: 1200 | M37: 🟢 Open Window
A38: 35 | B38: NWG-22-C | C38: =IFERROR(VLOOKUP($B38, 'Master Roster'!$A:$C, 3, FALSE), "") -> NWG | D38: =IFERROR(VLOOKUP($B38, 'Master Roster'!$A:$E, 5, FALSE), "") -> Ongani Madaliso Gabriel | E38: =IFERROR(VLOOKUP($B38, 'Master Roster'!$A:$F, 6, FALSE), "") -> 260771736585 | F38: =IFERROR(VLOOKUP($B38, 'Master Roster'!$A:$H, 8, FALSE), "") -> 1200 | G38: =IFERROR(VLOOKUP($B38, 'Master Roster'!$A:$G, 7, FALSE), "") -> 46174 | J38: Sep | K38: 10800 | L38: 0 | M38: ✅ Paid / Secured
A39: 36 | B39: NWG-22-D | C39: =IFERROR(VLOOKUP($B39, 'Master Roster'!$A:$C, 3, FALSE), "") -> NWG | D39: =IFERROR(VLOOKUP($B39, 'Master Roster'!$A:$E, 5, FALSE), "") -> Christopher Phiri | E39: =IFERROR(VLOOKUP($B39, 'Master Roster'!$A:$F, 6, FALSE), "") -> 260772109688 | F39: =IFERROR(VLOOKUP($B39, 'Master Roster'!$A:$H, 8, FALSE), "") -> 1200 | G39: =IFERROR(VLOOKUP($B39, 'Master Roster'!$A:$G, 7, FALSE), "") -> 46176 | J39: Sep | K39: 10800 | L39: 0 | M39: ✅ Paid / Secured
A40: 37 | B40: NWG-23-A | C40: =IFERROR(VLOOKUP($B40, 'Master Roster'!$A:$C, 3, FALSE), "") -> NWG | D40: =IFERROR(VLOOKUP($B40, 'Master Roster'!$A:$E, 5, FALSE), "") -> Vacant | E40: =IFERROR(VLOOKUP($B40, 'Master Roster'!$A:$F, 6, FALSE), "") -> 260973131421 | F40: =IFERROR(VLOOKUP($B40, 'Master Roster'!$A:$H, 8, FALSE), "") -> 1200 | G40: =IFERROR(VLOOKUP($B40, 'Master Roster'!$A:$G, 7, FALSE), "") -> 46198 | J40: Jul | K40: 8400 | L40: 0 | M40: Vacant
A41: 38 | B41: NWG-23-B | C41: =IFERROR(VLOOKUP($B41, 'Master Roster'!$A:$C, 3, FALSE), "") -> NWG | D41: =IFERROR(VLOOKUP($B41, 'Master Roster'!$A:$E, 5, FALSE), "") -> Catherine Mphande | E41: =IFERROR(VLOOKUP($B41, 'Master Roster'!$A:$F, 6, FALSE), "") -> 260963575803 | F41: =IFERROR(VLOOKUP($B41, 'Master Roster'!$A:$H, 8, FALSE), "") -> 1200 | G41: =IFERROR(VLOOKUP($B41, 'Master Roster'!$A:$G, 7, FALSE), "") -> 46187 | J41: Aug | K41: 9600 | L41: 1200 | M41: 🟢 Open Window
...

Sheet Receipt Template
B2: OFFICIAL RECEIPT | C2: Receipt No: | D2: {=IF(OR(ISBLANK(C5), C5=""), "", _xlfn.XLOOKUP(C5, 'Payments Log Archive'!A:A, 'Payments Log Archive'!N:N, "", 0, -1))} -> REC-0014
B5: Tenant ID: | C5: {=IF(OR(ISBLANK(C7), C7="Select"), "", _xlfn.XLOOKUP(C7, 'Monthly Billing Tab'!D4:D1001, 'Monthly Billing Tab'!B4:B1001, ""))} -> ANX-19-B
B6: Date: | C6: =TODAY() -> 46272
B7: Select Tenant Name: | C7: Chanda Lutashima
B8: Amount Paid: | C8: {=IF(OR(ISBLANK(C7), C7="Select"), "", LET(adj, _xlfn.XLOOKUP(C7, 'Monthly Billing Tab'!D4:D1001, 'Monthly Billing Tab'!H4:H1001, ""), IF(ISNUMBER(adj), ABS(adj), _xlfn.XLOOKUP(C7, 'Monthly Billing Tab'!D4:D1001, 'Monthly Billing Tab'!F4:F1001, ""))))} -> 1200
B9: Period Covered: | C9: {=IF(OR(ISBLANK(C7), C7="Select"), "", LET(entry_date, _xlfn.XLOOKUP(C7, 'Monthly Billing Tab'!D4:D1001, 'Monthly Billing Tab'!G4:G1001, 1), entry_day, DAY(entry_date), target_month, _xlfn.XLOOKUP(C7, 'Monthly Billing Tab'!D4:D1001, 'Monthly Billing Tab'!J4:J1001, ""), yr, IF(C10="", 2026, C10), IF(target_month="", "", LET(start_date, DATE(yr, MONTH(1&target_month), entry_day), TEXT(start_date, "d mmm yyyy") & " to " & TEXT(EDATE(start_date, 1) - 1, "d mmm yyyy")))))} -> 7 Sep 2026 to 6 Oct 2026
B11: Total Balance: | C11: {=IF(OR(ISBLANK(C7), C7="Select"), "", _xlfn.XLOOKUP(C7, 'Monthly Billing Tab'!D4:D1001, 'Monthly Billing Tab'!L4:L1001, ""))} -> 0
B12: Entry Date: | C12: =IF(OR(ISBLANK(C5), C5=""), "", VLOOKUP(C5, 'Master Roster'!A:G, 7, FALSE)) -> 46180
B13: WhatsApp: | C13: =IFERROR(__xludf.DUMMYFUNCTION("IF(OR(ISBLANK(C7), C7=""Select""), """", HYPERLINK(""https://wa.me/"" & IFERROR(INDEX(FILTER('Master Roster'!F:F, 'Master Roster'!E:E=C7, 'Master Roster'!F:F<>""""), 1), """") & ""?text="" & ENCODEURL(""Hello "" & IFERROR(IF(VLOOKUP(C5, 'Master Roster'!A:"&"J, 10, FALSE)=""Male"", ""Mr. "", ""Ms. ""), """") & C7 & "", this is your receipt for the payment of "" & C8 & "" covering "" & C9 & "". Thank you!""), ""Send WhatsApp Receipt""))"),"Send WhatsApp Receipt") -> Send WhatsApp Receipt
B15: Thank you for your payment!
C16: {=IF(OR(C4="", C4="--- Select ---"), "", HYPERLINK("https://wa.me/" & _xlfn.XLOOKUP(LEFT(C4, FIND(" - ", C4&" - ") - 1), 'Master Roster'!A:A, 'Master Roster'!F:F, "") & "?text=" & ENCODEURL("Hello " & IFERROR(IF(_xlfn.XLOOKUP(LEFT(C4, FIND(" - ", C4&" - ") - 1), 'Master Roster'!A:A, 'Master Roster'!J:J, "")="Male", "Mr. ", "Ms. "), "") & C7 & ", payment of K" & C8 & " received for " & C9 & ". Receipt No: " & D2), "💬 Send WhatsApp Receipt"))}

Sheet Payments Log Archive
A1: Payments Log Archive
A3: Unique ID | B3: Tenant Name | C3: Payment Date | D3: Month Covered | E3: Year | F3: Amount Paid | G3: Status | H3: Send Receipt | I3: Print Receipt | J3: Balance | K3: Cumulative Payments | L3: Receipt Issued | M3: Pending Receipts | N3: Receipt Number | O3: WhatsApp Receipt
A4: BBH-1-A | B4: {=IF(A4:A1002="", "", VLOOKUP(A4:A1002, 'Master Roster'!A:E, 5, FALSE))} -> Adrian mulale | C4: 2026-01-31 | D4: January | E4: 2026 | F4: 950 | G4: Paid | H4: 💬 Send Receipt | I4: Print Receipt | J4: =IF(A4="", "", IFERROR(VLOOKUP(A4, 'Master Roster'!A:H, 8, FALSE) - F4, "")) -> 0 | K4: {=IF(A4:A1002="", "", _xlfn.XLOOKUP(A4:A1002, 'Monthly Billing Tab'!B:B, 'Monthly Billing Tab'!K:K, ""))} -> 7600 | L4: FALSE | M4: =IFERROR(__xludf.DUMMYFUNCTION("LET(paid_ids, FILTER('Monthly Billing Tab'!B3:B1002, 'Monthly Billing Tab'!L3:L1002=0, 'Monthly Billing Tab'!B3:B1002<>"""", 'Monthly Billing Tab'!D3:D1002<>""Vacant""), paid_names, FILTER('Monthly Billing Tab'!D3:D1002, 'Monthly Billing Tab'!L3:L1002=0, "&"'Monthly Billing Tab'!B3:B1002<>"""", 'Monthly Billing Tab'!D3:D1002<>""Vacant""), paid_full, ARRAYFORMULA(paid_ids & "" - "" & paid_names), issued_full, FILTER(A4:A1002 & "" - "" & B4:B1002, L4:L1002=TRUE), VSTACK(""--- Select ---"", IFERROR(FILTER(paid_"&"full, ISNA(MATCH(paid_full, issued_full, 0))), ""No Pending Receipts"")))"),"--- Select ---") -> --- Select --- | N4: {=IF(A4:A1002="", "", "REC-" & TEXT(ROW(A4:A1002)-1, "0000"))} -> REC-0003 | O4: =IF(ISBLANK(A4), "", LET(entry_day, VLOOKUP(A4, 'Master Roster'!$A:$G, 7, FALSE), start_date, DATE(E4, MONTH(D4&" 1"), entry_day), end_date, EDATE(start_date, 1), period, TEXT(start_date, "mmm d, yyyy") & " - " & TEXT(end_date, "mmm d, yyyy"), HYPERLINK("https://wa.me/" & VLOOKUP(A4, 'Master Roster'!$A:$F, 6, FALSE) & "?text=" & ENCODEURL("Hello " & IFERROR(IF(VLOOKUP(A4, 'Master Roster'!$A:$J, 10, FALSE)="Male", "Mr. ", "Ms. "), "") & B4 & ", payment of K" & F4 & " received for " & period & ". Receipt No: " & N4), "Send Receipt"))) -> Send Receipt
A5: BBH-7-A | B5: Funny Muyamina | C5: 2026-01-05 | D5: January | E5: 2026 | F5: 900 | G5: Paid | H5: 💬 Send Receipt | I5: Print Receipt | J5: =IF(A5="", "", IFERROR(VLOOKUP(A5, 'Master Roster'!A:H, 8, FALSE) - F5, "")) -> 0 | K5: 7200 | L5: TRUE | M5: =IFERROR(__xludf.DUMMYFUNCTION("""COMPUTED_VALUE"""),"ANX-19-B - Chanda Lutashima") -> ANX-19-B - Chanda Lutashima | N5: REC-0004 | O5: =IF(ISBLANK(A5), "", LET(entry_day, VLOOKUP(A5, 'Master Roster'!$A:$G, 7, FALSE), start_date, DATE(E5, MONTH(D5&" 1"), entry_day), end_date, EDATE(start_date, 1), period, TEXT(start_date, "mmm d, yyyy") & " - " & TEXT(end_date, "mmm d, yyyy"), HYPERLINK("https://wa.me/" & VLOOKUP(A5, 'Master Roster'!$A:$F, 6, FALSE) & "?text=" & ENCODEURL("Hello " & IFERROR(IF(VLOOKUP(A5, 'Master Roster'!$A:$J, 10, FALSE)="Male", "Mr. ", "Ms. "), "") & B5 & ", payment of K" & F5 & " received for " & period & ". Receipt No: " & N5), "Send Receipt"))) -> Send Receipt
A6: BBH-1-A | B6: Adrian mulale | C6: 46178 | D6: June | E6: 2026 | F6: 950 | G6: Paid | H6: 💬 Send Receipt | I6: Print Receipt | J6: =IF(A6="", "", IFERROR(VLOOKUP(A6, 'Master Roster'!A:H, 8, FALSE) - F6, "")) -> 0 | K6: 7600 | L6: TRUE | M6: =IFERROR(__xludf.DUMMYFUNCTION("""COMPUTED_VALUE"""),"ANX-19-D - Lubono Ruthendo") -> ANX-19-D - Lubono Ruthendo | N6: REC-0005 | O6: =IF(ISBLANK(A6), "", LET(entry_day, VLOOKUP(A6, 'Master Roster'!$A:$G, 7, FALSE), start_date, DATE(E6, MONTH(D6&" 1"), entry_day), end_date, EDATE(start_date, 1), period, TEXT(start_date, "mmm d, yyyy") & " - " & TEXT(end_date, "mmm d, yyyy"), HYPERLINK("https://wa.me/" & VLOOKUP(A6, 'Master Roster'!$A:$F, 6, FALSE) & "?text=" & ENCODEURL("Hello " & IFERROR(IF(VLOOKUP(A6, 'Master Roster'!$A:$J, 10, FALSE)="Male", "Mr. ", "Ms. "), "") & B6 & ", payment of K" & F6 & " received for " & period & ". Receipt No: " & N6), "Send Receipt"))) -> Send Receipt
A7: BBH-6-C | B7: Zick Phiri | C7: 46178 | D7: June | E7: 2026 | F7: 900 | G7: Paid | H7: 💬 Send Receipt | I7: Print Receipt | J7: =IF(A7="", "", IFERROR(VLOOKUP(A7, 'Master Roster'!A:H, 8, FALSE) - F7, "")) -> 0 | K7: 7200 | L7: FALSE | M7: =IFERROR(__xludf.DUMMYFUNCTION("""COMPUTED_VALUE"""),"ANX-20-A - Steven Musonda") -> ANX-20-A - Steven Musonda | N7: REC-0006 | O7: =IF(ISBLANK(A7), "", LET(entry_day, VLOOKUP(A7, 'Master Roster'!$A:$G, 7, FALSE), start_date, DATE(E7, MONTH(D7&" 1"), entry_day), end_date, EDATE(start_date, 1), period, TEXT(start_date, "mmm d, yyyy") & " - " & TEXT(end_date, "mmm d, yyyy"), HYPERLINK("https://wa.me/" & VLOOKUP(A7, 'Master Roster'!$A:$F, 6, FALSE) & "?text=" & ENCODEURL("Hello " & IFERROR(IF(VLOOKUP(A7, 'Master Roster'!$A:$J, 10, FALSE)="Male", "Mr. ", "Ms. "), "") & B7 & ", payment of K" & F7 & " received for " & period & ". Receipt No: " & N7), "Send Receipt"))) -> Send Receipt
